Workbook

Sheet Project Omega
D17: Project Omega
D19: Financial review

Sheet Profit_Loss
A1: WHU Case Study
B2: Profit and loss accounts
H3: Actuals | K3: Business plan
B4: EURm | H4: 44561 | I4: 44926 | J4: 45291 | K4: 45657 | L4: 46022 | M4: 46387 | N4: CAGR 23-26 | O4: CAGR 21-23
C5: Total output | H5: 294 | I5: 297.2 | J5: 323.8 | K5: 384.2 | L5: 397.6 | M5: 415.5 | N5: =(M5/J5)^0.3333-1 -> 0.086661928 | O5: =(J5/H5)^0.5-1 -> 0.049457262
C6: growth % | H6: 0 | I6: =(I5/H5)-1 -> 0.010884354 | J6: =(J5/I5)-1 -> 0.089502019 | K6: =(K5/J5)-1 -> 0.1865349 | L6: =(L5/K5)-1 -> 0.034877668 | M6: =(M5/L5)-1 -> 0.045020121
C7: Material expenses | H7: -132.6 | I7: -129.2 | J7: -150.7 | K7: -172.8 | L7: -176.2 | M7: -181.7
C8: SG&A | H8: -158.5 | I8: -152.8 | J8: -154.9 | K8: -188.5 | L8: -194 | M8: -200.4
C9: EBITDA | H9: =H5+H7+H8 -> 2.9 | I9: =I5+I7+I8 -> 15.2 | J9: =J5+J7+J8 -> 18.2 | K9: =K5+K7+K8 -> 22.9 | L9: =L5+L7+L8 -> 27.4 | M9: =M5+M7+M8 -> 33.4 | N9: =(M9/J9)^0.3333-1 -> 0.22428606
C10: % of total output | H10: =H9/H5 -> 0.0098639456 | I10: =I9/I5 -> 0.051144011 | J10: =J9/J5 -> 0.056207536 | K10: =K9/K5 -> 0.059604373 | L10: =L9/L5 -> 0.068913481 | M10: =M9/M5 -> 0.080385078
C11: D&A | H11: -6.3 | I11: -6.8 | J11: -7.6 | K11: -7.7 | L11: -7.7 | M11: -7.8
C12: EBIT | H12: =H9+H11 -> -3.4 | I12: =I9+I11 -> 8.4 | J12: =J9+J11 -> 10.6 | K12: =K9+K11 -> 15.2 | L12: =L9+L11 -> 19.7 | M12: =M9+M11 -> 25.6 | N12: =(M12/J12)^0.3333-1 -> 0.34162745
C13: % of total output | H13: =H12/H5 -> -0.011564626 | I13: =I12/I5 -> 0.028263795 | J13: =J12/J5 -> 0.032736257 | K13: =K12/K5 -> 0.039562728 | L13: =L12/L5 -> 0.049547284 | M13: =M12/M5 -> 0.061612515
G16: Personnel expences | H16: -113.4 | I16: -116.7 | J16: -114.3 | K16: -124.5 | L16: -125.6 | M16: -128.7
G17: Other operating | H17: -65.8 | I17: -56.3 | J17: -59.8 | K17: -64.8 | L17: -69.3 | M17: -72.6
G18: Other operating income | H18: 20.7 | I18: 20.2 | J18: 19.2 | K18: 0.8 | L18: 0.9 | M18: 0.9
G19: SG&A | H19: =SUM(H16:H18) -> -158.5 | I19: =SUM(I16:I18) -> -152.8 | J19: =SUM(J16:J18) -> -154.9 | K19: =SUM(K16:K18) -> -188.5 | L19: =SUM(L16:L18) -> -194 | M19: =SUM(M16:M18) -> -200.4
G23: EBIT | H23: -3.4 | I23: 8.4 | J23: 10.6 | K23: 15.2 | L23: 19.7 | M23: 25.6
G24: D&A | H24: =H9-H23 -> 6.3 | I24: =I9-I23 -> 6.8 | J24: =J9-J23 -> 7.6 | K24: =K9-K23 -> 7.7 | L24: =L9-L23 -> 7.7 | M24: =M9-M23 -> 7.8

Sheet Balance_Sheet
A1: WHU Case Study
B2: Balance sheet
H3: Actuals | K3: Business plan
B4: EURm | C4: EURm | H4: =Profit_Loss!H4 -> 44561 | I4: =Profit_Loss!I4 -> 44926 | J4: =Profit_Loss!J4 -> 45291 | K4: =Profit_Loss!K4 -> 45657 | L4: =Profit_Loss!L4 -> 46022 | M4: =Profit_Loss!M4 -> 46387
C5: Non-current assets | H5: =H6+H7+H8 -> 198.6 | I5: =I6+I7+I8 -> 178.1 | J5: =J6+J7+J8 -> 164 | K5: =K6+K7+K8 -> 153.5 | L5: =L6+L7+L8 -> 147.4 | M5: =M6+M7+M8 -> 144.1
C6: Intangible assets | H6: 157.2 | I6: 143.1 | J6: 131.8 | K6: 127.2 | L6: 125.6 | M6: 125.6
C7: Tangible assets | H7: 28.4 | I7: 28.6 | J7: 26.6 | K7: 24.3 | L7: 20.4 | M7: 17.1
C8: Other non current assets | H8: 13 | I8: 6.4 | J8: 5.6 | K8: 2 | L8: 1.4 | M8: 1.4
C9: Current assets | H9: =H10+H11+H12+H13+H14 -> 297.2 | I9: =I10+I11+I12+I13+I14 -> 316.4 | J9: =J10+J11+J12+J13+J14 -> 289.9 | K9: =K10+K11+K12+K13+K14 -> 294.4 | L9: =L10+L11+L12+L13+L14 -> 303.4 | M9: =M10+M11+M12+M13+M14 -> 326.8
C10: Inventories | H10: 36.1 | I10: 48.2 | J10: 36.2 | K10: 50.5 | L10: 46.8 | M10: 50.5
C11: Trade receivables | H11: 58.7 | I11: 41.3 | J11: 47.3 | K11: 61.7 | L11: 67.6 | M11: 69.2
C12: Trade receivables POC | H12: 14.4 | I12: 20.2 | J12: 30.8 | K12: 6.4
C13: Other receivables and assets | H13: 17.9 | I13: 15.4 | J13: 22.5 | K13: 19.9 | L13: 19.9 | M13: 19.9
C14: Cash and cash equivalents | H14: 170.1 | I14: 191.3 | J14: 153.1 | K14: 155.9 | L14: 169.1 | M14: 187.2
C15: Total assets | H15: =H6+H7+H8+H10+H11+H12+H13+H14 -> 495.8 | I15: =I6+I7+I8+I10+I11+I12+I13+I14 -> 494.5 | J15: =J6+J7+J8+J10+J11+J12+J13+J14 -> 453.9 | K15: =K6+K7+K8+K10+K11+K12+K13+K14 -> 447.9 | L15: =L6+L7+L8+L10+L11+L12+L13+L14 -> 450.8 | M15: =M6+M7+M8+M10+M11+M12+M13+M14 -> 470.9
C16: Equity | H16: 266.8 | I16: 246 | J16: 227.2 | K16: 217.1 | L16: 221.3 | M16: 232.8
C17: Non-current liabilities | H17: =H18+H19+H20+H21+H22 -> 109.8 | I17: =I18+I19+I20+I21+I22 -> 106.3 | J17: =J18+J19+J20+J21+J22 -> 94.3 | K17: =K18+K19+K20+K21+K22 -> 92.5 | L17: =L18+L19+L20+L21+L22 -> 92.5 | M17: =M18+M19+M20+M21+M22 -> 95.3
C18: Pension provisions | H18: 78.5 | I18: 78.5 | J18: 74.5 | K18: 71 | L18: 71 | M18: 71
C19: Other provisions | H19: 4.5 | I19: 3 | J19: 1.8 | K19: 2.9 | L19: 0 | M19: 0
C20: Other liabilities | H20: 1.6 | I20: 1.6 | J20: 0.8 | K20: 2 | L20: 21.5 | M20: 24.3
C21: Financial liabilities | H21: 0 | I21: 0 | J21: 0 | K21: 0 | L21: 0 | M21: 0
C22: Deferred tax liabilities | H22: 25.2 | I22: 23.2 | J22: 17.2 | K22: 16.6
C23: Current liabilities | H23: =H24+H25+H26+H27+H28 -> 119.1 | I23: =I24+I25+I26+I27+I28 -> 142.3 | J23: =J24+J25+J26+J27+J28 -> 132.3 | K23: =K24+K25+K26+K27+K28 -> 138.4 | L23: =L24+L25+L26+L27+L28 -> 137.2 | M23: =M24+M25+M26+M27+M28 -> 142.9
C24: Trade payables | H24: 44.2 | I24: 42.2 | J24: 37.7 | K24: 40.7 | L24: 40.9 | M24: 42.6
C25: Advance payments received | H25: 25.6 | I25: 41.4 | J25: 39.3 | K25: 35.4 | L25: 39.8 | M25: 43.8
C26: Current financial liabilities | H26: 0.2 | I26: 1.6 | J26: 1.1 | K26: 0 | L26: 0 | M26: 0
C27: Other provisions | H27: 18.5 | I27: 26.7 | J27: 18.2 | K27: 21.3 | L27: 19.9 | M27: 19.9
C28: Other liabilities | H28: 30.6 | I28: 30.4 | J28: 36 | K28: 41 | L28: 36.6 | M28: 36.6
C29: Total equity and liabilities | H29: =H16+H18+H19+H20+H21+H22+H24+H25+H26+H27+H28 -> 495.7 | I29: =I16+I18+I19+I20+I21+I22+I24+I25+I26+I27+I28 -> 494.6 | J29: =J16+J18+J19+J20+J21+J22+J24+J25+J26+J27+J28 -> 453.8 | K29: =K16+K18+K19+K20+K21+K22+K24+K25+K26+K27+K28 -> 448 | L29: =L16+L18+L19+L20+L21+L22+L24+L25+L26+L27+L28 -> 451 | M29: =M16+M18+M19+M20+M21+M22+M24+M25+M26+M27+M28 -> 471
G31: Other financial assets | H31: 0.9 | I31: 0.6 | J31: 0.5 | K31: 0.5 | L31: 0.5 | M31: 0.5
G32: Receivables and other assets | H32: 0.4 | I32: 0.5 | J32: 0.6 | K32: 1.2 | L32: 0.6 | M32: 0.6
G33: Deferred taxes | H33: 11.7 | I33: 5.3 | J33: 4.5 | K33: 0.3 | L33: 0.3 | M33: 0.3
G34: Other non current assets | H34: 13 | I34: 6.4 | J34: 5.6 | K34: =SUM(K31:K33) -> 2 | L34: =SUM(L31:L33) -> 1.4 | M34: =SUM(M31:M33) -> 1.4

Sheet NWC
A1: WHU Case Study
B2: Net working capital
H3: Actuals | K3: Business plan
B4: EURm | H4: =Profit_Loss!H4 -> 44561 | I4: =Profit_Loss!I4 -> 44926 | J4: =Profit_Loss!J4 -> 45291 | K4: =Profit_Loss!K4 -> 45657 | L4: =Profit_Loss!L4 -> 46022 | M4: =Profit_Loss!M4 -> 46387
C5: Trade receivables | H5: =Balance_Sheet!H11+Balance_Sheet!H12 -> 73.1 | I5: =Balance_Sheet!I11+Balance_Sheet!I12 -> 61.5 | J5: =Balance_Sheet!J11+Balance_Sheet!J12 -> 78.1 | K5: =Balance_Sheet!K11+Balance_Sheet!K12 -> 68.1 | L5: =Balance_Sheet!L11+Balance_Sheet!L12 -> 67.6 | M5: =Balance_Sheet!M11+Balance_Sheet!M12 -> 69.2
C6: Inventories | H6: =Balance_Sheet!H10 -> 36.1 | I6: =Balance_Sheet!I10 -> 48.2 | J6: =Balance_Sheet!J10 -> 36.2 | K6: =Balance_Sheet!K10 -> 50.5 | L6: =Balance_Sheet!L10 -> 46.8 | M6: =Balance_Sheet!M10 -> 50.5
C7: Trade payables | H7: =Balance_Sheet!H24 -> 44.2 | I7: =Balance_Sheet!I24 -> 42.2 | J7: =Balance_Sheet!J24 -> 37.7 | K7: =Balance_Sheet!K24 -> 40.7 | L7: =Balance_Sheet!L24 -> 40.9 | M7: =Balance_Sheet!M24 -> 42.6
C8: Trade working capital | H8: =H5+H6-H7 -> 65 | I8: =I5+I6-I7 -> 67.5 | J8: =J5+J6-J7 -> 76.6 | K8: =K5+K6-K7 -> 77.9 | L8: =L5+L6-L7 -> 73.5 | M8: =M5+M6-M7 -> 77.1
C9: Advance payments received | H9: =Balance_Sheet!H25 -> 25.6 | I9: =Balance_Sheet!I25 -> 41.4 | J9: =Balance_Sheet!J25 -> 39.3 | K9: =Balance_Sheet!K25 -> 35.4 | L9: =Balance_Sheet!L25 -> 39.8 | M9: =Balance_Sheet!M25 -> 43.8
C10: Net working capital | H10: =H8-H9 -> 39.4 | I10: =I8-I9 -> 26.1 | J10: =J8-J9 -> 37.3 | K10: =K8-K9 -> 42.5 | L10: =L8-L9 -> 33.7 | M10: =M8-M9 -> 33.3
C11: % of sales | H11: =H10/Profit_Loss!H5 -> 0.13401361 | I11: =I10/Profit_Loss!I5 -> 0.08781965 | J11: =J10/Profit_Loss!J5 -> 0.11519456 | K11: =K10/Profit_Loss!K5 -> 0.11061947 | L11: =L10/Profit_Loss!L5 -> 0.084758551 | M11: =M10/Profit_Loss!M5 -> 0.080144404

Sheet Cash_Flow
A1: WHU Case Study
B2: Cash flow statement
H3: Actuals | K3: Business plan | N3: Normalisation
B4: EURm | C4: EURm | H4: =Profit_Loss!H4 -> 44561 | I4: =Profit_Loss!I4 -> 44926 | J4: =Profit_Loss!J4 -> 45291 | K4: =Profit_Loss!K4 -> 45657 | L4: =Profit_Loss!L4 -> 46022 | M4: =Profit_Loss!M4 -> 46387 | N4: =+EDATE(M4,12) -> 46752
C5: EBIT | H5: =Calcs!C14 -> -3.4 | I5: =Calcs!D14 -> 8.4 | J5: =Calcs!E14 -> 10.6 | K5: =Calcs!F14 -> 15.2 | L5: =Calcs!G14 -> 19.7 | M5: =Calcs!H14 -> 25.6 | N5: =Calcs!I14 -> 21.555717
C6: Taxes | H6: =H5*WACC!$E$15 -> -1.02 | I6: =I5*WACC!$E$15 -> 2.52 | J6: =J5*WACC!$E$15 -> 3.18 | K6: =K5*WACC!$E$15 -> 4.56 | L6: =L5*WACC!$E$15 -> 5.91 | M6: =M5*WACC!$E$15 -> 7.68 | N6: =N5*WACC!$E$15 -> 6.4667152
C7: NOPAT | H7: =H5-H6 -> -2.38 | I7: =I5-I6 -> 5.88 | J7: =J5-J6 -> 7.42 | K7: =K5-K6 -> 10.64 | L7: =L5-L6 -> 13.79 | M7: =M5-M6 -> 17.92 | N7: =N5-N6 -> 15.089002
C8: D&A | H8: =-Calcs!C12 -> 6.3 | I8: =-Calcs!D12 -> 6.8 | J8: =-Calcs!E12 -> 7.6 | K8: =-Calcs!F12 -> 7.7 | L8: =-Calcs!G12 -> 7.7 | M8: =-Calcs!H12 -> 7.8 | N8: =-Calcs!I12 -> 7.956
C9: Capex | H9: =Calcs!C21 -> 0 | I9: =Calcs!D21 -> -7.1 | J9: =Calcs!E21 -> -7 | K9: =Calcs!F21 -> -9 | L9: =Calcs!G21 -> -8.4 | M9: =Calcs!H21 -> -8.6 | N9: =Calcs!I21 -> -8.772
C10: Change in NWC | H10: =-Calcs!C18 -> 0 | I10: =-Calcs!D18 -> -13.3 | J10: =-Calcs!E18 -> 11.2 | K10: =-Calcs!F18 -> 5.2 | L10: =-Calcs!G18 -> -8.8 | M10: =-Calcs!H18 -> -0.4 | N10: =-Calcs!I18 -> 0.666
C11: Free cash flow | H11: =H7+H8+H9-H10 -> 3.92 | I11: =I7+I8+I9-I10 -> 18.88 | J11: =J7+J8+J9-J10 -> -3.18 | K11: =K7+K8+K9-K10 -> 4.14 | L11: =L7+L8+L9-L10 -> 21.89 | M11: =M7+M8+M9-M10 -> 17.52 | N11: =N7+N8+N9-N10 -> 13.607002 | O11: =N11*(1+Calcs!I7) -> 13.879142 | P11: Perpetuity
K13: 1 | L13: 2 | M13: 3 | N13: 4
C14: Discount factor | K14: =1/(1+$D$22)^K13 -> 0.92149712 | L14: =1/(1+$D$22)^L13 -> 0.84915693 | M14: =1/(1+$D$22)^M13 -> 0.78249567 | N14: =1/(1+$D$22)^N13 -> 0.7210675
C15: Discounted FCF | K15: =K11*K14 -> 3.8149981 | L15: =L11*L14 -> 18.588045 | M15: =M11*M14 -> 13.709324 | N15: =N11*N14 -> 9.8115669
C16: Terminal value | N16: =O11/(D22-D23) -> 212.901
C17: Discounted TV | N17: =N14*N16 -> 153.51599
C18: Enterprise Value, EURm | M18: Median | N18: =+SUM(K15:N15)+N17 -> 199.43993 | O18: =N18*0.95 -> 189.46793 | P18: =N18*1.05 -> 209.41192
C19: Equity Value, EURm (EBIT) | M19: Median | N19: =N18-G20 -> 237.63993 | O19: =N19*0.95 -> 225.75793 | P19: =N19*1.05 -> 249.52192
C20: Bridge (calculated before) | G20: -38.2
C22: WACC | D22: =WACC!E16 -> 0.085190591
C23: Long-term Growth Rate | D23: 0.02
C24: EBITDA/Sales | D24: =Calcs!I11 -> 0.069634311
C26: Sensitivity analysis
C27: Sensitivity analysis
E30: LT growth rate
D31: =N18 -> 199.43993 | E31: =F31-0.005 -> 0.005 | F31: =G31-0.005 -> 0.01 | G31: =H31-0.005 -> 0.015 | H31: 0.02 | I31: =H31+0.005 -> 0.025 | J31: =I31+0.005 -> 0.03 | K31: =J31+0.005 -> 0.035
C32: TV EBITDA / Sales | D32: =D33-0.005 -> 0.0546 | E32: 128.83251 | F32: 133.76604 | G32: 139.40244 | H32: 145.90345 | I32: 153.48453 | J32: 162.43922 | K32: 173.17806
D33: =D34-0.005 -> 0.0596 | E33: 143.09396 | F33: 149.05151 | G33: 155.85783 | H33: 163.70822 | I33: 172.86285 | J33: 183.67622 | K33: 196.64405
D34: =D35-0.005 -> 0.0646 | E34: 157.35541 | F34: 164.33699 | G34: 172.31322 | H34: 181.51298 | I34: 192.24118 | J34: 204.91322 | K34: 220.11005
D35: 0.0696 | E35: 171.61686 | F35: 179.62246 | G35: 188.76861 | H35: 199.31775 | I35: 211.61951 | J35: 226.15023 | K35: 243.57605
D36: =D35+0.005 -> 0.0746 | E36: 185.87831 | F36: 194.90793 | G36: 205.224 | H36: 217.12251 | I36: 230.99783 | J36: 247.38723 | K36: 267.04205
D37: =D36+0.005 -> 0.0796 | E37: 200.13976 | F37: 210.19341 | G37: 221.67939 | H37: 234.92728 | I37: 250.37616 | J37: 268.62423 | K37: 290.50805
D38: =D37+0.005 -> 0.0846 | E38: 214.40121 | F38: 225.47888 | G38: 238.13478 | H38: 252.73204 | I38: 269.75449 | J38: 289.86123 | K38: 313.97405
E40: Cost of capital
D41: =N18 -> 199.43993 | E41: =F41+0.005 -> 0.1002 | F41: =G41+0.005 -> 0.0952 | G41: =H41+0.005 -> 0.0902 | H41: 0.0852 | I41: =H41-0.005 -> 0.0802 | J41: =I41-0.005 -> 0.0752 | K41: =J41-0.005 -> 0.0702
C42: Long term growth | D42: =D43-0.005 -> 0.005 | E42: 143.79382 | F42: 151.77498 | G42: 160.68709 | H42: 170.70407 | I42: 182.0461 | J42: 194.99609 | K42: 209.9237
D43: =D44-0.005 -> 0.01 | E43: 149.30955 | F43: 158.05141 | G43: 167.87651 | H43: 179.00069 | I43: 191.7013 | J43: 206.34073 | K43: 223.4018
D44: =D45-0.005 -> 0.015 | E44: 155.47266 | F44: 165.11044 | G44: 176.02197 | H44: 188.47917 | I44: 202.83735 | J44: 219.56987 | K44: 239.32159
D45: 0.02 | E45: 162.40424 | F45: 173.10817 | G45: 185.32776 | H45: 199.4114 | I45: 215.82324 | J45: 235.19559 | K45: 258.41265
D46: =D45+0.005 -> 0.025 | E46: 170.25757 | F46: 182.24518 | G46: 196.06081 | H46: 212.15961 | I46: 231.16165 | J46: 253.934 | K46: 281.72739
...

Sheet WACC
A1: WHU Case Study
D4: WACC calculation
D5: 1. Target financial structure
D6: Equity / (Equity + Debt) | E6: 0.5
D7: Debt / (Equity + Debt) | E7: =1-E6 -> 0.5
D8: 2. Cost of equity | E8: =E9+E12*E10 -> 0.13347858
D9: Risk free rate | E9: =E23 -> 0.024918
D10: Market premium | E10: =G35 -> 0.063859166
D11: Unlevered beta | E11: 1
D12: Re-levered beta | E12: =$E$11*(1+(1-E15)*(E7/E6)) -> 1.7
D13: 3. Cost of debt | E13: =(E9+E14)*(1-E15) -> 0.0369026
D14: Debt premium | E14: 0.0278
D15: Tax rate | E15: 0.3
D16: Theoretical WACC | E16: =E6*E8+E7*E13 -> 0.085190591
D22: Risk free rate (Swap rate):
D23: 45289 | E23: =2.4918/100 -> 0.024918
D24: Average (19 years) | E24: =2.05151264896509/100 -> 0.020515126
D25: Median (19 years) | E25: =1.8826/100 -> 0.018826
D28: Market premium weighted by Operations region
D29: Operations - Region | E29: Footprint | F29: Rel % | G29: ERP (Damodaran)
D30: Germany | E30: =4600+5500+16024+4272+2260 -> 32656 | F30: =E30/$E$34 -> 0.80218134 | G30: 0.0601
D31: France | E31: =2000+300 -> 2300 | F31: =E31/$E$34 -> 0.056498563 | G31: 0.0628
D32: Spain | E32: =2000 -> 2000 | F32: =E32/$E$34 -> 0.049129185 | G32: 0.0729
D33: India | E33: =3753 -> 3753 | F33: =E33/$E$34 -> 0.092190916 | G33: 0.0924
D34: Total | E34: =SUM(E30:E33) -> 40709 | F34: =E34/$E$34 -> 1
F35: Weighted Market Premium | G35: =F30*G30+F31*G31+F32*G32+F33*G33 -> 0.063859166

Sheet Calcs
A1: WHU Case Study
B3: Statement of income, normalised
B4: EURm | C4: Actuals | F4: Business plan | I4: Normalisation
C5: =Profit_Loss!H4 -> 44561 | D5: =Profit_Loss!I4 -> 44926 | E5: =Profit_Loss!J4 -> 45291 | F5: =Profit_Loss!K4 -> 45657 | G5: =Profit_Loss!L4 -> 46022 | H5: =Profit_Loss!M4 -> 46387 | I5: =+EDATE(H5,12) -> 46752
B6: Sales | C6: =Profit_Loss!H5 -> 294 | D6: =Profit_Loss!I5 -> 297.2 | E6: =Profit_Loss!J5 -> 323.8 | F6: =Profit_Loss!K5 -> 384.2 | G6: =Profit_Loss!L5 -> 397.6 | H6: =Profit_Loss!M5 -> 415.5 | I6: =+H6*(1+I7) -> 423.81
B7: % growth | D7: =+D6/C6-1 -> 0.010884354 | E7: =+E6/D6-1 -> 0.089502019 | F7: =+F6/E6-1 -> 0.1865349 | G7: =+G6/F6-1 -> 0.034877668 | H7: =+H6/G6-1 -> 0.045020121 | I7: 0.02 | J7: Assumed as a historical GDP growth
B8: COGS | C8: =Profit_Loss!H7 -> -132.6 | D8: =Profit_Loss!I7 -> -129.2 | E8: =Profit_Loss!J7 -> -150.7 | F8: =Profit_Loss!K7 -> -172.8 | G8: =Profit_Loss!L7 -> -176.2 | H8: =Profit_Loss!M7 -> -181.7
B9: SG&A | C9: =Profit_Loss!H8 -> -158.5 | D9: =Profit_Loss!I8 -> -152.8 | E9: =Profit_Loss!J8 -> -154.9 | F9: =Profit_Loss!K8 -> -188.5 | G9: =Profit_Loss!L8 -> -194 | H9: =Profit_Loss!M8 -> -200.4
B10: EBITDA | C10: =+C6+C8+C9 -> 2.9 | D10: =+D6+D8+D9 -> 15.2 | E10: =+E6+E8+E9 -> 18.2 | F10: =+F6+F8+F9 -> 22.9 | G10: =+G6+G8+G9 -> 27.4 | H10: =+H6+H8+H9 -> 33.4 | I10: =+I11*I6 -> 29.511717
B11: % of sales | C11: =+C10/C6 -> 0.0098639456 | D11: =+D10/D6 -> 0.051144011 | E11: =+E10/E6 -> 0.056207536 | F11: =+F10/F6 -> 0.059604373 | G11: =+G10/G6 -> 0.068913481 | H11: =+H10/H6 -> 0.080385078 | I11: =AVERAGE(F11:H11) -> 0.069634311 | J11: Average from Business plan
B12: D & A | C12: =Profit_Loss!H11 -> -6.3 | D12: =Profit_Loss!I11 -> -6.8 | E12: =Profit_Loss!J11 -> -7.6 | F12: =Profit_Loss!K11 -> -7.7 | G12: =Profit_Loss!L11 -> -7.7 | H12: =Profit_Loss!M11 -> -7.8 | I12: =I13*I6 -> -7.956
B13: % of sales | C13: =+C12/C6 -> -0.021428571 | D13: =+D12/D6 -> -0.022880215 | E13: =+E12/E6 -> -0.023471279 | F13: =+F12/F6 -> -0.020041645 | G13: =+G12/G6 -> -0.019366197 | H13: =+H12/H6 -> -0.018772563 | I13: =H13 -> -0.018772563
B14: EBIT | C14: =+C10+C12 -> -3.4 | D14: =+D10+D12 -> 8.4 | E14: =+E10+E12 -> 10.6 | F14: =+F10+F12 -> 15.2 | G14: =+G10+G12 -> 19.7 | H14: =+H10+H12 -> 25.6 | I14: =+I10+I12 -> 21.555717
B15: % of sales | C15: =+C14/C6 -> -0.011564626 | D15: =+D14/D6 -> 0.028263795 | E15: =+E14/E6 -> 0.032736257 | F15: =+F14/F6 -> 0.039562728 | G15: =+G14/G6 -> 0.049547284 | H15: =+H14/H6 -> 0.061612515 | I15: =+I14/I6 -> 0.050861747
B17: Net working capital (NWC) | C17: =NWC!H10 -> 39.4 | D17: =NWC!I10 -> 26.1 | E17: =NWC!J10 -> 37.3 | F17: =NWC!K10 -> 42.5 | G17: =NWC!L10 -> 33.7 | H17: =NWC!M10 -> 33.3 | I17: =+I19*I6 -> 33.966
B18: Change in NWC | D18: =+C17-D17 -> 13.3 | E18: =+D17-E17 -> -11.2 | F18: =+E17-F17 -> -5.2 | G18: =+F17-G17 -> 8.8 | H18: =+G17-H17 -> 0.4 | I18: =+H17-I17 -> -0.666
B19: % of sales | C19: =C17/C6 -> 0.13401361 | D19: =D17/D6 -> 0.08781965 | E19: =E17/E6 -> 0.11519456 | F19: =F17/F6 -> 0.11061947 | G19: =G17/G6 -> 0.084758551 | H19: =H17/H6 -> 0.080144404 | I19: =H19 -> 0.080144404 | J19: Assumed Last Year in the Business Plan
B21: Capex | D21: -7.1 | E21: -7 | F21: -9 | G21: -8.4 | H21: -8.6 | I21: =I6*I22 -> -8.772 | J21: From the PDF balance sheet
B22: % of total output | D22: =+D21/D6 -> -0.023889637 | E22: =+E21/E6 -> -0.021618283 | F22: =+F21/F6 -> -0.023425299 | G22: =+G21/G6 -> -0.021126761 | H22: =+H21/H6 -> -0.020697954 | I22: =H22 -> -0.020697954 | J22: Assumed Last Year in the Business Plan
B24: Output for PowerPoint
B26: EURm | C26: =+C5 -> 44561 | D26: =+D5 -> 44926 | E26: =+E5 -> 45291 | F26: =+F5 -> 45657 | G26: =+G5 -> 46022 | H26: =+H5 -> 46387 | I26: 2027E
B28: =+B6 -> Sales | C28: =+C6 -> 294 | D28: =+D6 -> 297.2 | E28: =+E6 -> 323.8 | F28: =+F6 -> 384.2 | G28: =+G6 -> 397.6 | H28: =+H6 -> 415.5
B29: =+B7 -> % growth | D29: =+D7 -> 0.010884354 | E29: =+E7 -> 0.089502019 | F29: =+F7 -> 0.1865349 | G29: =+G7 -> 0.034877668 | H29: =+H7 -> 0.045020121
B31: =+B10 -> EBITDA | C31: =+C10 -> 2.9 | D31: =+D10 -> 15.2 | E31: =+E10 -> 18.2 | F31: =+F10 -> 22.9 | G31: =+G10 -> 27.4 | H31: =+H10 -> 33.4
B32: =+B11 -> % of sales | C32: =+C11 -> 0.0098639456 | D32: =+D11 -> 0.051144011 | E32: =+E11 -> 0.056207536 | F32: =+F11 -> 0.059604373 | G32: =+G11 -> 0.068913481 | H32: =+H11 -> 0.080385078
B34: =+B12 -> D & A | C34: =+C12 -> -6.3 | D34: =+D12 -> -6.8 | E34: =+E12 -> -7.6 | F34: =+F12 -> -7.7 | G34: =+G12 -> -7.7 | H34: =+H12 -> -7.8
B35: =B13 -> % of sales | C35: =+C13 -> -0.021428571 | D35: =+D13 -> -0.022880215 | E35: =+E13 -> -0.023471279 | F35: =+F13 -> -0.020041645 | G35: =+G13 -> -0.019366197 | H35: =+H13 -> -0.018772563
B37: =+B14 -> EBIT | C37: =+C14 -> -3.4 | D37: =+D14 -> 8.4 | E37: =+E14 -> 10.6 | F37: =+F14 -> 15.2 | G37: =+G14 -> 19.7 | H37: =+H14 -> 25.6
B38: =+B15 -> % of sales | C38: =+C15 -> -0.011564626 | D38: =+D15 -> 0.028263795 | E38: =+E15 -> 0.032736257 | F38: =+F15 -> 0.039562728 | G38: =+G15 -> 0.049547284 | H38: =+H15 -> 0.061612515
B40: =+B17 -> Net working capital (NWC) | C40: =+C17 -> 39.4 | D40: =+D17 -> 26.1 | E40: =+E17 -> 37.3 | F40: =+F17 -> 42.5 | G40: =+G17 -> 33.7 | H40: =+H17 -> 33.3
B41: =B19 -> % of sales | C41: =+C19 -> 0.13401361 | D41: =+D19 -> 0.08781965 | E41: =+E19 -> 0.11519456 | F41: =+F19 -> 0.11061947 | G41: =+G19 -> 0.084758551 | H41: =+H19 -> 0.080144404
B43: =B21 -> Capex | D43: =D21 -> -7.1 | E43: =E21 -> -7 | F43: =F21 -> -9 | G43: =G21 -> -8.4 | H43: =H21 -> -8.6
B44: =B22 -> % of total output | D44: =D22 -> -0.023889637 | E44: =E22 -> -0.021618283 | F44: =F22 -> -0.023425299 | G44: =G22 -> -0.021126761 | H44: =H22 -> -0.020697954
B46: WACC | C46: =WACC!E16 -> 0.085190591
B49: Sensitivity analysis
D52: LT growth rate
C53: =Cash_Flow!N18 -> 199.43993 | D53: =E53-0.005 -> 0.005 | E53: =F53-0.005 -> 0.01 | F53: =G53-0.005 -> 0.015 | G53: 0.02 | H53: =G53+0.005 -> 0.025 | I53: =H53+0.005 -> 0.03 | J53: =I53+0.005 -> 0.035
B54: TV EBITDA / Sales | C54: =C55-0.005 -> 0.0546 | D54: 148.5904 | E54: 147.70784 | F54: 146.8122 | G54: 145.90345 | H54: 144.98161 | I54: 144.04667 | J54: 143.09864
C55: =C56-0.005 -> 0.0596 | D55: 165.89084 | E55: 165.17559 | F55: 164.44805 | G55: 163.70822 | H55: 162.95609 | I55: 162.19167 | J55: 161.41496
C56: =C57-0.005 -> 0.0646 | D56: 183.19129 | E56: 182.64334 | F56: 182.0839 | G56: 181.51298 | H56: 180.93057 | I56: 180.33667 | J56: 179.73129
...
