Workbook
Name a: #REF!
Name a: #REF!
Name a: #REF!
Name Columns: #REF!
Name Columns: #REF!
Name Columns: #REF!
Name EBIT: #REF!
Name EBIT: #REF!
Name IQ_CH: 110000
Name IQ_CQ: 5000
Name IQ_CY: 10000
Name IQ_DAILY: 500000
Name IQ_FH: 100000
Name IQ_FQ: 500
Name IQ_FY: 1000
Name IQ_LTM: 2000
Name IQ_MONTH: 15000
Name IQ_NTM: 6000
Name IQ_WEEK: 50000
Name IQ_YTD: 3000
Name languageinput: #REF!
Name languageinput: #REF!
Name languageinput: #REF!
Name Tradings: #REF!
Name Tradings: #REF!
Name Tradings: #REF!

Sheet __FDSCACHE__
B1: This sheet contains Factset binary data for use with this workbook's =FDS codes. Modifying the worksheet's contents may damage the workbook's =FDS functionality.

Sheet Project Omega
D8: Project Omega
D10: Trading Multiples Analysis

Sheet __APW_ACTIVE_FIELD_RESTORE__

Sheet LinkingMetadata

Sheet CIQ_LinkingNames
A1: CIQANR_d9b112d924bd4db49d6c8ba0418839e5 | B1: 45447.393

Sheet Financials_hard coded
B2: Financials (EURm)
E7: Local | F7: Exchange | H7: Market cap | I7: Bridge | J7: EV | L7: Sales (EURm) | Q7: EBITDA (EURm) | V7: EBIT (EURm) | AA7: Net income (EURm)
B8: Ticker | C8: Companies | E8: currency | F8: rate | H8: (EURm) | I8: (EURm) | J8: (EURm) | L8: 45291 | M8: 45657 | N8: 46022 | O8: 46387 | Q8: 45291 | R8: 45657 | S8: 46022 | T8: 46387 | V8: 45291 | W8: 45657 | X8: 46022 | Y8: 46387 | AA8: 45291 | AB8: 45657 | AC8: 46022 | AD8: 46387 | AF8: EBITDA Margin | AG8: EBIT Margin
L9: FY2023 | M9: FY2024 | N9: FY2025 | O9: FY2026 | Q9: FY2023 | R9: FY2024 | S9: FY2025 | T9: FY2026 | V9: FY2023 | W9: FY2024 | X9: FY2025 | Y9: FY2026
B10: OM:ALFA | C10: Alfa Laval AB | E10: SEK | F10: 0.08753 | H10: 17554.591 | I10: ='Equity Bridge (simple)'!M10 -> 0 | J10: =+I10+H10 -> 17554.591 | L10: 5721.2828 | M10: 6121.1208 | N10: 6451.8569 | O10: 6724.2899 | Q10: 996.48809 | R10: 1176.45 | S10: 1260.234 | T10: 1333.8341 | V10: 823.58477 | W10: 1001.1347 | X10: 1083.5158 | Y10: 1148.4025 | AA10: 569.44747 | AB10: 712.71129 | AC10: 780.55911 | AD10: 837.64371 | AF10: =Q10/L10*100 -> 17.417214 | AG10: =V10/L10*100 -> 14.395107
B11: OTCCH:001268465 | C11: Bobst Group SA | E11: CHF | F11: 1.02055 | H11: 965.96212 | I11: ='Equity Bridge (simple)'!M11 -> 130.22218 | J11: =+I11+H11 -> 1096.1843 | L11: 2106.1247 | M11: na | N11: na | O11: na | Q11: 188.87759 | R11: na | S11: na | T11: na | V11: 160.83603 | W11: na | X11: na | Y11: na | AA11: 127.52997 | AB11: na | AC11: na | AD11: na | AF11: =Q11/L11*100 -> 8.9680153 | AG11: =V11/L11*100 -> 7.6365861
B12: TSE:6407 | C12: CKD Corp. | E12: JPY | F12: 0.00587 | H12: 1198.2796 | I12: ='Equity Bridge (simple)'!M12 -> -64.29998 | J12: =+I12+H12 -> 1133.9796 | L12: 1104.0383 | M12: 823.7563 | N12: 888.99308 | O12: 1003.5588 | Q12: 192.45912 | R12: 117.85602 | S12: 154.3711 | T12: 199.78372 | V12: 146.58244 | W12: 75.61277 | X12: 107.69959 | Y12: 145.05312 | AA12: 102.38822 | AB12: 0 | AC12: 0 | AD12: 0 | AF12: =Q12/L12*100 -> 17.432286 | AG12: =V12/L12*100 -> 13.276934
B13: XTRA:DEZ | C13: Deutz AG | E13: EUR | F13: 1 | H13: 658.48836 | I13: ='Equity Bridge (simple)'!M13 -> 0 | J13: =+I13+H13 -> 658.48836 | L13: 2063.2 | M13: 2008.3 | N13: 2304.9 | O13: 2443.8 | Q13: 188.7 | R13: 209.7 | S13: 246.3731 | T13: 277.16052 | V13: 132.6 | W13: 116.68 | X13: 150.9 | Y13: 180.8 | AA13: 81.9 | AB13: 89.32 | AC13: 112.66 | AD13: 135.475 | AF13: =Q13/L13*100 -> 9.1459868 | AG13: =V13/L13*100 -> 6.4269097
B14: TSE:6141 | C14: DMG Mori co. | E14: JPY | F14: 0.00587 | H14: 3706.0245 | I14: ='Equity Bridge (simple)'!M14 -> 0 | J14: =+I14+H14 -> 3706.0245 | L14: 3462.2128 | M14: 3249.4363 | N14: 3464.2849 | O14: 3633.4336 | Q14: 495.52419 | R14: 515.75528 | S14: 581.58679 | T14: 633.22166 | V14: 325.33055 | W14: 343.63902 | X14: 400.39287 | Y14: 445.05408 | AA14: 217.85402 | AB14: na | AC14: na | AD14: na | AF14: =Q14/L14*100 -> 14.312355 | AG14: =V14/L14*100 -> 9.3966077
B15: XTRA:DUE | C15: Dürr AG | E15: EUR | F15: 1 | H15: 1622.0968 | I15: ='Equity Bridge (simple)'!M15 -> 0 | J15: =+I15+H15 -> 1622.0968 | L15: 4627.334 | M15: 4830.7766 | N15: 4997.0693 | O15: 5198.3644 | Q15: 285.604 | R15: 389.79815 | S15: 456.07663 | T15: 485.37016 | V15: 205.624 | W15: 265.01667 | X15: 322.65 | Y15: 373.75 | AA15: 111.981 | AB15: 153.90883 | AC15: 198.2509 | AD15: 228.11065 | AF15: =Q15/L15*100 -> 6.1721069 | AG15: =V15/L15*100 -> 4.4436818
B16: XTRA:G1A | C16: Gea Group AG | E16: EUR | F16: 1 | H16: 6441.47 | I16: ='Equity Bridge (simple)'!M16 -> 643.612 | J16: =+I16+H16 -> 7085.082 | L16: 5373.491 | M16: 5468.9982 | N16: 5630.3151 | O16: 5844.2816 | Q16: 597.081 | R16: 801.93084 | S16: 834.56619 | T16: 877.03472 | V16: 512.521 | W16: 618.12173 | X16: 647.99194 | Y16: 666.66304 | AA16: 392.765 | AB16: 439.89013 | AC16: 462.76394 | AD16: 496.33208 | AF16: =Q16/L16*100 -> 11.111603 | AG16: =V16/L16*100 -> 9.5379521
B17: XTRA:KRN | C17: Krones AG | E17: EUR | F17: 1 | H17: 3980.7271 | I17: ='Equity Bridge (simple)'!M17 -> -68.334 | J17: =+I17+H17 -> 3912.3931 | L17: 4765.479 | M17: 5290.9195 | N17: 5676.1437 | O17: 5953.1904 | Q17: 463.434 | R17: 537.39476 | S17: 616.51451 | T17: 672.20381 | V17: 315.669 | W17: 375.14707 | X17: 454.74651 | Y17: 506.79624 | AA17: 224.511 | AB17: 276.40599 | AC17: 335.53172 | AD17: 373.22502 | AF17: =Q17/L17*100 -> 9.7248147 | AG17: =V17/L17*100 -> 6.624077
B21: Stock prices and consensus estimates as of current
B22: Date | C22: current
B23: Currency | C23: EUR
B28: Peer Selection Criteria
B30: 1. Industry & Segment | D30: Companies operating in the packaging machinery, engineering, or industrial machinery sectors.
B31: 2. Product Overlap | D31: Companies manufacturing similar types of machinery and equipment, particularly: Packaging machinery (filling, sealing, wrapping, etc.), focused on food, beverage, and dairy industries. Providers of integrated systems or after-sales services.
B32: 3. Geography | D32: Companies with a strong presence in Europe (Omega's core market), but also consider global players with significant operations or sales in regions where Omega is expanding (e.g., North America, Asia-Pacific).
B33: 4. Size | D33: Companies with comparable financial metrics, factor 2x: Revenue within 0.5x to 2.0x of Omega’s EUR 325.5m revenue (approximately EUR 160m–650m range). Market Capitalization: Within a reasonable range around Omega.
B34: 5. Profitability Metrics | D34: Companies with EBIT/EBITDA margins in a range comparable to Omega's current and forecast margins (~5%-8% EBITDA; ~3,3%-6% EBIT margins).
B35: 6. Market Trends | D35: Companies exposed to similar market trends, such as: Growing demand for packaging machinery; for automation; for eco-friendly and efficient packaging solutions.
B37: Peer Selection Outcome
C38: Company | D38: Alignment Score
B39: OM:ALFA | C39: Alfa Laval AB | D39: =SUM(I51:I56)&" / 6" -> 1 / 6 | E39: 1
B40: OTCCH:001268465 | C40: Bobst Group SA | D40: =SUM(I59:I64)&" / 6" -> 5 / 6 | E40: 1 | F40: -> Included
B41: TSE:6407 | C41: CKD Corp. | D41: =SUM(I67:I72)&" / 6" -> 4 / 6 | E41: 1 | F41: -> Included
B42: XTRA:DEZ | C42: Deutz AG | D42: =SUM(I75:I80)&" / 6" -> 2 / 6 | E42: 1
B43: TSE:6141 | C43: DMG Mori co. | D43: =SUM(I75:I80)&" / 6" -> 2 / 6 | E43: 1
B44: XTRA:DUE | C44: Dürr AG | D44: =SUM(I91:I96)&" / 6" -> 3 / 6 | E44: 1
B45: XTRA:G1A | C45: Gea Group AG | D45: =SUM(I99:I104)&" / 6" -> 4 / 6 | E45: 1 | F45: -> Included
B46: XTRA:KRN | C46: Krones AG | D46: =SUM(I107:I112)&" / 6" -> 4 / 6 | E46: 1 | F46: -> Included
B48: Peer Justification:
B50: Alfa Laval AB | D50: Outcome for Alfa Laval | I50: Met Criteria?
B51: Industry & Segment | D51: No overlap with packaging machinery | I51: 0
B52: Product Overlap | D52: No alignment with packaging machinery (heat exchange) | I52: 0
B53: Geography | D53: Strong presence in Europe and globally | I53: 1
B54: Size | D54: Revenue far exceeds range (EUR 160M–650M) | I54: 0
B55: Profitability Metrics | D55: EBITDA margin (18.5%) in 2023; exceed range | I55: 0
B56: Market Trends | D56: Unrelated (exposed to energy efficiency, water treatment) | I56: 0
...

Sheet Equity Bridge (simple)
B2: Equity Bridge
E7: Local | F7: Exchange | I7: Net debt/(net cash) | J7: Pensions | K7: Minorities | M7: Sum
C8: Companies | E8: currency | F8: rate | I8: (EURm) | J8: (EURm) | K8: (EURm) | M8: (EURm)
C10: Alfa Laval AB | E10: =+'Financials_hard coded'!E10 -> SEK | F10: =+'Financials_hard coded'!F10 -> 0.08753
C11: Bobst Group SA | E11: =+'Financials_hard coded'!E11 -> CHF | F11: =+'Financials_hard coded'!F11 -> 1.02055 | I11: =('BS Bobst'!J31+'BS Bobst'!J37-'BS Bobst'!J22)*F11 -> 136.54959 | J11: =('BS Bobst'!J33+'BS Bobst'!J39-'BS Bobst'!J11)*F11 -> -8.062345 | K11: ='BS Bobst'!J29*F11 -> 1.734935 | M11: =+SUM(I11:K11) -> 130.22218
C12: CKD Corp. | E12: =+'Financials_hard coded'!E12 -> JPY | F12: =+'Financials_hard coded'!F12 -> 0.00587 | I12: =('BS CKD'!K49+'BS CKD'!K50+'BS CKD'!K51+'BS CKD'!K61+'BS CKD'!K62-'BS CKD'!K9)*F12 -> -58.36541 | J12: =('BS CKD'!K65+'BS CKD'!K66-'BS CKD'!K35)*F12 -> -5.93457 | K12: 0 | M12: =+SUM(I12:K12) -> -64.29998
C13: Deutz AG | E13: =+'Financials_hard coded'!E13 -> EUR | F13: =+'Financials_hard coded'!F13 -> 1
C14: DMG Mori co. | E14: =+'Financials_hard coded'!E14 -> JPY | F14: =+'Financials_hard coded'!F14 -> 0.00587
C15: Dürr AG | E15: =+'Financials_hard coded'!E15 -> EUR | F15: =+'Financials_hard coded'!F15 -> 1
C16: Gea Group AG | E16: =+'Financials_hard coded'!E16 -> EUR | F16: =+'Financials_hard coded'!F16 -> 1 | I16: =('BS GEA'!L44+'BS GEA'!L53-'BS GEA'!L24)*F16 -> -282.872 | J16: =('BS GEA'!L43+'BS GEA'!L52)*F16 -> 926.072 | K16: ='BS GEA'!L39*'Equity Bridge (simple)'!F16 -> 0.412 | M16: =+SUM(I16:K16) -> 643.612
C17: Krones AG | E17: =+'Financials_hard coded'!E17 -> EUR | F17: =+'Financials_hard coded'!F17 -> 1 | I17: =('BS Krones'!N50+'BS Krones'!N57+'BS Krones'!N52+'BS Krones'!N61-'BS Krones'!N25)*F17 -> -247.24 | J17: ='BS Krones'!N46*'Equity Bridge (simple)'!F17 -> 178.444 | K17: ='BS Krones'!N43*F17 -> 0.462 | M17: =+SUM(I17:K17) -> -68.334

Sheet Equity Bridge
B2: Equity Bridge
E7: Local | F7: Exchange | I7: Net (debt)/net cash | J7: Pensions | K7: Minorities | M7: Sum
C8: Companies | E8: currency | F8: rate | I8: (EURm) | J8: (EURm) | K8: (EURm) | M8: (EURm)
C10: Alfa Laval AB | E10: =+'Financials_hard coded'!E10 -> SEK | F10: =+'Financials_hard coded'!F10 -> 0.08753 | I10: =+(#REF!+#REF!+#REF!+#REF!-#REF!-#REF!-#REF!-#REF!-#REF!-#REF!)*F10 -> #REF! | J10: =+(-#REF!+#REF!)*F10 -> #REF! | K10: =345*F10 -> 30.19785 | M10: =+SUM(I10:K10) -> #REF!
C11: Bobst Group SA | E11: =+'Financials_hard coded'!E11 -> CHF | F11: =+'Financials_hard coded'!F11 -> 1.02055 | I11: =+(#REF!+#REF!+#REF!+#REF!+#REF!+#REF!+#REF!+#REF!-#REF!-#REF!-#REF!)*F11 -> #REF! | J11: =+(-#REF!-#REF!+#REF!)*F11 -> #REF! | K11: =1.7*F11 -> 1.734935 | M11: =+SUM(I11:K11) -> #REF!
C12: CKD Corp. | E12: =+'Financials_hard coded'!E12 -> JPY | F12: =+'Financials_hard coded'!F12 -> 0.00587 | I12: =+(#REF!+#REF!-#REF!-#REF!-#REF!)*F12 -> #REF! | J12: =+(-#REF!-#REF!+#REF!)*F12 -> #REF! | K12: 0 | M12: =+SUM(I12:K12) -> #REF!
C13: Deutz AG | E13: =+'Financials_hard coded'!E13 -> EUR | F13: =+'Financials_hard coded'!F13 -> 1 | I13: =+(#REF!+#REF!+#REF!-#REF!-#REF!-#REF!+#REF!-#REF!) -> #REF! | J13: =+(-#REF!-#REF!) -> #REF! | K13: 0 | M13: =+SUM(I13:K13) -> #REF!
C14: DMG Mori co. | E14: =+'Financials_hard coded'!E14 -> JPY | F14: =+'Financials_hard coded'!F14 -> 0.00587 | I14: =+(#REF!+#REF!+#REF!+#REF!+#REF!+#REF!+#REF!-#REF!-#REF!-#REF!-#REF!-#REF!) -> #REF! | J14: =+(-#REF!) -> #REF! | K14: 20.223 | M14: =+SUM(I14:K14) -> #REF!
C15: Dürr AG | E15: =+'Financials_hard coded'!E15 -> EUR | F15: =+'Financials_hard coded'!F15 -> 1 | I15: =+(#REF!+#REF!+#REF!+#REF!+#REF!+#REF!+#REF!-#REF!-#REF!-#REF!-#REF!-#REF!-#REF!-#REF!) -> #REF! | J15: =+(-#REF!) -> #REF! | K15: 7.071 | M15: =+SUM(I15:K15) -> #REF!
C16: Gea Group AG | E16: =+'Financials_hard coded'!E16 -> EUR | F16: =+'Financials_hard coded'!F16 -> 1 | I16: =+(#REF!+#REF!+#REF!+#REF!+#REF!-#REF!-#REF!-#REF!) -> #REF! | J16: =+(-#REF!-#REF!) -> #REF! | K16: 0.412 | M16: =+SUM(I16:K16) -> #REF!
C17: Krones AG | E17: =+'Financials_hard coded'!E17 -> EUR | F17: =+'Financials_hard coded'!F17 -> 1 | I17: =+(#REF!+#REF!+#REF!+#REF!-#REF!-#REF!-#REF!-#REF!) -> #REF! | J17: =+(-#REF!) -> #REF! | K17: 0.462 | M17: =+SUM(I17:K17) -> #REF!

Sheet _CIQHiddenCacheSheet
